[2025-01-13T17:41:07.098+0000] {local_task_job_runner.py:123} INFO - ::group::Pre task execution logs
[2025-01-13T17:41:07.140+0000] {taskinstance.py:2613} INFO - Dependencies all met for dep_context=non-requeueable deps ti=<TaskInstance: fetch_and_store_amazon_books.create_table scheduled__2024-07-11T00:00:00+00:00 [queued]>
[2025-01-13T17:41:07.160+0000] {taskinstance.py:2613} INFO - Dependencies all met for dep_context=requeueable deps ti=<TaskInstance: fetch_and_store_amazon_books.create_table scheduled__2024-07-11T00:00:00+00:00 [queued]>
[2025-01-13T17:41:07.406+0000] {taskinstance.py:2866} INFO - Starting attempt 2 of 2
[2025-01-13T17:41:07.522+0000] {taskinstance.py:2889} INFO - Executing <Task(PostgresOperator): create_table> on 2024-07-11 00:00:00+00:00
[2025-01-13T17:41:07.538+0000] {warnings.py:112} WARNING - /home/***/.local/lib/python3.12/site-packages/***/task/task_runner/standard_task_runner.py:70: DeprecationWarning: This process (pid=375) is multi-threaded, use of fork() may lead to deadlocks in the child.
  pid = os.fork()

[2025-01-13T17:41:07.541+0000] {standard_task_runner.py:72} INFO - Started process 395 to run task
[2025-01-13T17:41:07.546+0000] {standard_task_runner.py:104} INFO - Running: ['***', 'tasks', 'run', 'fetch_and_store_amazon_books', 'create_table', 'scheduled__2024-07-11T00:00:00+00:00', '--job-id', '168', '--raw', '--subdir', 'DAGS_FOLDER/app.py', '--cfg-path', '/tmp/tmpavc7c03u']
[2025-01-13T17:41:07.549+0000] {standard_task_runner.py:105} INFO - Job 168: Subtask create_table
[2025-01-13T17:41:07.807+0000] {task_command.py:467} INFO - Running <TaskInstance: fetch_and_store_amazon_books.create_table scheduled__2024-07-11T00:00:00+00:00 [running]> on host fd1694d66b9b
[2025-01-13T17:41:08.106+0000] {taskinstance.py:3132} INFO - Exporting env vars: AIRFLOW_CTX_DAG_OWNER='***' AIRFLOW_CTX_DAG_ID='fetch_and_store_amazon_books' AIRFLOW_CTX_TASK_ID='create_table' AIRFLOW_CTX_EXECUTION_DATE='2024-07-11T00:00:00+00:00' AIRFLOW_CTX_TRY_NUMBER='2' AIRFLOW_CTX_DAG_RUN_ID='scheduled__2024-07-11T00:00:00+00:00'
[2025-01-13T17:41:08.112+0000] {logging_mixin.py:190} INFO - Task instance is in running state
[2025-01-13T17:41:08.113+0000] {logging_mixin.py:190} INFO -  Previous state of the Task instance: queued
[2025-01-13T17:41:08.114+0000] {logging_mixin.py:190} INFO - Current task name:create_table state:running start_date:2025-01-13 17:41:07.141554+00:00
[2025-01-13T17:41:08.116+0000] {logging_mixin.py:190} INFO - Dag name:fetch_and_store_amazon_books and current dag run status:running
[2025-01-13T17:41:08.117+0000] {taskinstance.py:731} INFO - ::endgroup::
[2025-01-13T17:41:08.118+0000] {sql.py:278} INFO - Executing: 
    CREATE TABLE IF NOT EXISTS books (
        id SERIAL PRIMARY KEY,
        title TEXT NOT NULL,
        authors TEXT,
        price TEXT,
        rating TEXT
    );
    
[2025-01-13T17:41:08.144+0000] {base.py:84} INFO - Retrieving connection 'books_connection'
[2025-01-13T17:41:08.163+0000] {base.py:84} INFO - Retrieving connection 'books_connection'
[2025-01-13T17:41:08.175+0000] {taskinstance.py:3311} ERROR - Task failed with exception
Traceback (most recent call last):
  File "/home/airflow/.local/lib/python3.12/site-packages/airflow/models/taskinstance.py", line 767, in _execute_task
    result = _execute_callable(context=context, **execute_callable_kwargs)
             ^^^^^^^^^^^^^^^^^^^^^^^^^^^^^^^^^^^^^^^^^^^^^^^^^^^^^^^^^^^^^
  File "/home/airflow/.local/lib/python3.12/site-packages/airflow/models/taskinstance.py", line 733, in _execute_callable
    return ExecutionCallableRunner(
           ^^^^^^^^^^^^^^^^^^^^^^^^
  File "/home/airflow/.local/lib/python3.12/site-packages/airflow/utils/operator_helpers.py", line 252, in run
    return self.func(*args, **kwargs)
           ^^^^^^^^^^^^^^^^^^^^^^^^^^
  File "/home/airflow/.local/lib/python3.12/site-packages/airflow/models/baseoperator.py", line 422, in wrapper
    return func(self, *args, **kwargs)
           ^^^^^^^^^^^^^^^^^^^^^^^^^^^
  File "/home/airflow/.local/lib/python3.12/site-packages/airflow/providers/common/sql/operators/sql.py", line 284, in execute
    output = hook.run(
             ^^^^^^^^^
  File "/home/airflow/.local/lib/python3.12/site-packages/airflow/providers/common/sql/hooks/sql.py", line 494, in run
    with self._create_autocommit_connection(autocommit) as conn:
         ^^^^^^^^^^^^^^^^^^^^^^^^^^^^^^^^^^^^^^^^^^^^^^
  File "/usr/local/lib/python3.12/contextlib.py", line 137, in __enter__
    return next(self.gen)
           ^^^^^^^^^^^^^^
  File "/home/airflow/.local/lib/python3.12/site-packages/airflow/providers/common/sql/hooks/sql.py", line 618, in _create_autocommit_connection
    with closing(self.get_conn()) as conn:
                 ^^^^^^^^^^^^^^^
  File "/home/airflow/.local/lib/python3.12/site-packages/airflow/providers/postgres/hooks/postgres.py", line 189, in get_conn
    self.conn = psycopg2.connect(**conn_args)
                ^^^^^^^^^^^^^^^^^^^^^^^^^^^^^
  File "/home/airflow/.local/lib/python3.12/site-packages/psycopg2/__init__.py", line 122, in connect
    conn = _connect(dsn, connection_factory=connection_factory, **kwasync)
           ^^^^^^^^^^^^^^^^^^^^^^^^^^^^^^^^^^^^^^^^^^^^^^^^^^^^^^^^^^^^^^^
psycopg2.OperationalError: connection to server at "172.20.0.4", port 5432 failed: FATAL:  database "amazon_books" does not exist

[2025-01-13T17:41:08.241+0000] {logging_mixin.py:190} INFO - Task instance in failure state
[2025-01-13T17:41:08.242+0000] {logging_mixin.py:190} INFO - Task start:2025-01-13 17:41:07.141554+00:00 end:2025-01-13 17:41:08.240079+00:00 duration:1.098525
[2025-01-13T17:41:08.243+0000] {logging_mixin.py:190} INFO - Task:<Task(PostgresOperator): create_table> dag:<DAG: fetch_and_store_amazon_books> dagrun:<DagRun fetch_and_store_amazon_books @ 2024-07-11 00:00:00+00:00: scheduled__2024-07-11T00:00:00+00:00, state:running, queued_at: 2025-01-13 17:08:57.966639+00:00. externally triggered: False>
[2025-01-13T17:41:08.244+0000] {logging_mixin.py:190} INFO - Failure caused by connection to server at "172.20.0.4", port 5432 failed: FATAL:  database "amazon_books" does not exist
[2025-01-13T17:41:08.245+0000] {taskinstance.py:1225} INFO - Marking task as FAILED. dag_id=fetch_and_store_amazon_books, task_id=create_table, run_id=scheduled__2024-07-11T00:00:00+00:00, execution_date=20240711T000000, start_date=20250113T174107, end_date=20250113T174108
[2025-01-13T17:41:08.363+0000] {taskinstance.py:340} INFO - ::group::Post task execution logs
[2025-01-13T17:41:08.379+0000] {standard_task_runner.py:124} ERROR - Failed to execute job 168 for task create_table (connection to server at "172.20.0.4", port 5432 failed: FATAL:  database "amazon_books" does not exist
; 395)
Traceback (most recent call last):
  File "/home/airflow/.local/lib/python3.12/site-packages/airflow/task/task_runner/standard_task_runner.py", line 117, in _start_by_fork
    ret = args.func(args, dag=self.dag)
          ^^^^^^^^^^^^^^^^^^^^^^^^^^^^^
  File "/home/airflow/.local/lib/python3.12/site-packages/airflow/cli/cli_config.py", line 49, in command
    return func(*args, **kwargs)
           ^^^^^^^^^^^^^^^^^^^^^
  File "/home/airflow/.local/lib/python3.12/site-packages/airflow/utils/cli.py", line 116, in wrapper
    return f(*args, **kwargs)
           ^^^^^^^^^^^^^^^^^^
  File "/home/airflow/.local/lib/python3.12/site-packages/airflow/cli/commands/task_command.py", line 483, in task_run
    task_return_code = _run_task_by_selected_method(args, _dag, ti)
                       ^^^^^^^^^^^^^^^^^^^^^^^^^^^^^^^^^^^^^^^^^^^^
  File "/home/airflow/.local/lib/python3.12/site-packages/airflow/cli/commands/task_command.py", line 256, in _run_task_by_selected_method
    return _run_raw_task(args, ti)
           ^^^^^^^^^^^^^^^^^^^^^^^
  File "/home/airflow/.local/lib/python3.12/site-packages/airflow/cli/commands/task_command.py", line 341, in _run_raw_task
    return ti._run_raw_task(
           ^^^^^^^^^^^^^^^^^
  File "/home/airflow/.local/lib/python3.12/site-packages/airflow/utils/session.py", line 97, in wrapper
    return func(*args, session=session, **kwargs)
           ^^^^^^^^^^^^^^^^^^^^^^^^^^^^^^^^^^^^^^
  File "/home/airflow/.local/lib/python3.12/site-packages/airflow/models/taskinstance.py", line 3005, in _run_raw_task
    return _run_raw_task(
           ^^^^^^^^^^^^^^
  File "/home/airflow/.local/lib/python3.12/site-packages/airflow/models/taskinstance.py", line 273, in _run_raw_task
    TaskInstance._execute_task_with_callbacks(
  File "/home/airflow/.local/lib/python3.12/site-packages/airflow/models/taskinstance.py", line 3159, in _execute_task_with_callbacks
    result = self._execute_task(context, task_orig)
             ^^^^^^^^^^^^^^^^^^^^^^^^^^^^^^^^^^^^^^
  File "/home/airflow/.local/lib/python3.12/site-packages/airflow/models/taskinstance.py", line 3183, in _execute_task
    return _execute_task(self, context, task_orig)
           ^^^^^^^^^^^^^^^^^^^^^^^^^^^^^^^^^^^^^^^
  File "/home/airflow/.local/lib/python3.12/site-packages/airflow/models/taskinstance.py", line 767, in _execute_task
    result = _execute_callable(context=context, **execute_callable_kwargs)
             ^^^^^^^^^^^^^^^^^^^^^^^^^^^^^^^^^^^^^^^^^^^^^^^^^^^^^^^^^^^^^
  File "/home/airflow/.local/lib/python3.12/site-packages/airflow/models/taskinstance.py", line 733, in _execute_callable
    return ExecutionCallableRunner(
           ^^^^^^^^^^^^^^^^^^^^^^^^
  File "/home/airflow/.local/lib/python3.12/site-packages/airflow/utils/operator_helpers.py", line 252, in run
    return self.func(*args, **kwargs)
           ^^^^^^^^^^^^^^^^^^^^^^^^^^
  File "/home/airflow/.local/lib/python3.12/site-packages/airflow/models/baseoperator.py", line 422, in wrapper
    return func(self, *args, **kwargs)
           ^^^^^^^^^^^^^^^^^^^^^^^^^^^
  File "/home/airflow/.local/lib/python3.12/site-packages/airflow/providers/common/sql/operators/sql.py", line 284, in execute
    output = hook.run(
             ^^^^^^^^^
  File "/home/airflow/.local/lib/python3.12/site-packages/airflow/providers/common/sql/hooks/sql.py", line 494, in run
    with self._create_autocommit_connection(autocommit) as conn:
         ^^^^^^^^^^^^^^^^^^^^^^^^^^^^^^^^^^^^^^^^^^^^^^
  File "/usr/local/lib/python3.12/contextlib.py", line 137, in __enter__
    return next(self.gen)
           ^^^^^^^^^^^^^^
  File "/home/airflow/.local/lib/python3.12/site-packages/airflow/providers/common/sql/hooks/sql.py", line 618, in _create_autocommit_connection
    with closing(self.get_conn()) as conn:
                 ^^^^^^^^^^^^^^^
  File "/home/airflow/.local/lib/python3.12/site-packages/airflow/providers/postgres/hooks/postgres.py", line 189, in get_conn
    self.conn = psycopg2.connect(**conn_args)
                ^^^^^^^^^^^^^^^^^^^^^^^^^^^^^
  File "/home/airflow/.local/lib/python3.12/site-packages/psycopg2/__init__.py", line 122, in connect
    conn = _connect(dsn, connection_factory=connection_factory, **kwasync)
           ^^^^^^^^^^^^^^^^^^^^^^^^^^^^^^^^^^^^^^^^^^^^^^^^^^^^^^^^^^^^^^^
psycopg2.OperationalError: connection to server at "172.20.0.4", port 5432 failed: FATAL:  database "amazon_books" does not exist

[2025-01-13T17:41:08.464+0000] {local_task_job_runner.py:266} INFO - Task exited with return code 1
[2025-01-13T17:41:08.531+0000] {taskinstance.py:3895} INFO - 0 downstream tasks scheduled from follow-on schedule check
[2025-01-13T17:41:08.617+0000] {local_task_job_runner.py:245} INFO - ::endgroup::
